<?xml version="1.0" encoding="UTF-8"?>
<testng-results skipped="4" failed="2" ignored="0" total="8" passed="2">
  <reporter-output>
  </reporter-output>
  <suite name="StockCircles Automation Testing" duration-ms="24" started-at="2019-05-23T17:52:38Z" finished-at="2019-05-23T17:52:38Z">
    <groups>
      <group name="CompatibilityTesting">
        <method signature="TestClass.test2()[pri:0, instance:TestClass@2344fc66]" name="test2" class="TestClass"/>
      </group> <!-- CompatibilityTesting -->
      <group name="FunctionalTesting">
        <method signature="TestClass.test1()[pri:0, instance:TestClass@2344fc66]" name="test1" class="TestClass"/>
        <method signature="TestClass.test2()[pri:0, instance:TestClass@2344fc66]" name="test2" class="TestClass"/>
        <method signature="TestClass.test3()[pri:0, instance:TestClass@2344fc66]" name="test3" class="TestClass"/>
      </group> <!-- FunctionalTesting -->
      <group name="RegressionTesting">
        <method signature="TestClass.test1()[pri:0, instance:TestClass@2344fc66]" name="test1" class="TestClass"/>
        <method signature="TestClass.test3()[pri:0, instance:TestClass@2344fc66]" name="test3" class="TestClass"/>
        <method signature="TestClass.test4()[pri:0, instance:TestClass@2344fc66]" name="test4" class="TestClass"/>
        <method signature="TestClass.test5()[pri:0, instance:TestClass@2344fc66]" name="test5" class="TestClass"/>
      </group> <!-- RegressionTesting -->
    </groups>
    <test name="CompatibilityTesting" duration-ms="24" started-at="2019-05-23T17:52:38Z" finished-at="2019-05-23T17:52:38Z">
      <class name="TestClass">
        <test-method status="PASS" signature="beforeSuite()[pri:0, instance:TestClass@2344fc66]" name="beforeSuite" is-config="true" duration-ms="9" started-at="2019-05-23T17:52:38Z" finished-at="2019-05-23T17:52:38Z">
          <reporter-output>
          </reporter-output>
        </test-method> <!-- beforeSuite -->
        <test-method status="PASS" signature="beforeClass()[pri:0, instance:TestClass@2344fc66]" name="beforeClass" is-config="true" duration-ms="0" started-at="2019-05-23T17:52:38Z" finished-at="2019-05-23T17:52:38Z">
          <reporter-output>
          </reporter-output>
        </test-method> <!-- beforeClass -->
        <test-method status="PASS" signature="test1()[pri:0, instance:TestClass@2344fc66]" name="test1" duration-ms="0" started-at="2019-05-23T17:52:38Z" finished-at="2019-05-23T17:52:38Z">
          <reporter-output>
          </reporter-output>
        </test-method> <!-- test1 -->
        <test-method status="PASS" signature="resetPage()[pri:0, instance:TestClass@2344fc66]" name="resetPage" is-config="true" duration-ms="0" started-at="2019-05-23T17:52:38Z" finished-at="2019-05-23T17:52:38Z">
          <reporter-output>
          </reporter-output>
        </test-method> <!-- resetPage -->
        <test-method status="SKIP" signature="test3()[pri:0, instance:TestClass@2344fc66]" name="test3" duration-ms="2" started-at="2019-05-23T17:52:38Z" finished-at="2019-05-23T17:52:38Z">
          <exception class="java.lang.AssertionError">
            <message>
              <![CDATA[expected [2] but found [1]]]>
            </message>
            <full-stacktrace>
              <![CDATA[java.lang.AssertionError: expected [2] but found [1]
at org.testng.Assert.fail(Assert.java:96)
at org.testng.Assert.failNotEquals(Assert.java:776)
at org.testng.Assert.assertEqualsImpl(Assert.java:137)
at org.testng.Assert.assertEquals(Assert.java:118)
at org.testng.Assert.assertEquals(Assert.java:453)
at org.testng.Assert.assertEquals(Assert.java:463)
at TestClass.test3(TestClass.java:77)
at sun.reflect.NativeMethodAccessorImpl.invoke0(Native Method)
at sun.reflect.NativeMethodAccessorImpl.invoke(NativeMethodAccessorImpl.java:62)
at sun.reflect.DelegatingMethodAccessorImpl.invoke(DelegatingMethodAccessorImpl.java:43)
at java.lang.reflect.Method.invoke(Method.java:498)
at org.testng.internal.MethodInvocationHelper.invokeMethod(MethodInvocationHelper.java:124)
at org.testng.internal.Invoker.invokeMethod(Invoker.java:583)
at org.testng.internal.Invoker.invokeTestMethod(Invoker.java:719)
at org.testng.internal.Invoker.invokeTestMethods(Invoker.java:989)
at org.testng.internal.TestMethodWorker.invokeTestMethods(TestMethodWorker.java:125)
at org.testng.internal.TestMethodWorker.run(TestMethodWorker.java:109)
at org.testng.TestRunner.privateRun(TestRunner.java:648)
at org.testng.TestRunner.run(TestRunner.java:505)
at org.testng.SuiteRunner.runTest(SuiteRunner.java:455)
at org.testng.SuiteRunner.access$000(SuiteRunner.java:40)
at org.testng.SuiteRunner$SuiteWorker.run(SuiteRunner.java:489)
at org.testng.internal.thread.ThreadUtil$1.call(ThreadUtil.java:52)
at java.util.concurrent.FutureTask.run(FutureTask.java:266)
at java.util.concurrent.ThreadPoolExecutor.runWorker(ThreadPoolExecutor.java:1149)
at java.util.concurrent.ThreadPoolExecutor$Worker.run(ThreadPoolExecutor.java:624)
at java.lang.Thread.run(Thread.java:748)
]]>
            </full-stacktrace>
          </exception> <!-- java.lang.AssertionError -->
          <reporter-output>
          </reporter-output>
        </test-method> <!-- test3 -->
        <test-method status="PASS" signature="resetPage()[pri:0, instance:TestClass@2344fc66]" name="resetPage" is-config="true" duration-ms="0" started-at="2019-05-23T17:52:38Z" finished-at="2019-05-23T17:52:38Z">
          <reporter-output>
          </reporter-output>
        </test-method> <!-- resetPage -->
        <test-method status="PASS" signature="resetPage()[pri:0, instance:TestClass@2344fc66]" name="resetPage" is-config="true" duration-ms="0" started-at="2019-05-23T17:52:38Z" finished-at="2019-05-23T17:52:38Z">
          <reporter-output>
          </reporter-output>
        </test-method> <!-- resetPage -->
        <test-method status="SKIP" signature="test3()[pri:0, instance:TestClass@2344fc66]" name="test3" duration-ms="1" started-at="2019-05-23T17:52:38Z" finished-at="2019-05-23T17:52:38Z">
          <exception class="java.lang.AssertionError">
            <message>
              <![CDATA[expected [2] but found [1]]]>
            </message>
            <full-stacktrace>
              <![CDATA[java.lang.AssertionError: expected [2] but found [1]
at org.testng.Assert.fail(Assert.java:96)
at org.testng.Assert.failNotEquals(Assert.java:776)
at org.testng.Assert.assertEqualsImpl(Assert.java:137)
at org.testng.Assert.assertEquals(Assert.java:118)
at org.testng.Assert.assertEquals(Assert.java:453)
at org.testng.Assert.assertEquals(Assert.java:463)
at TestClass.test3(TestClass.java:77)
at sun.reflect.NativeMethodAccessorImpl.invoke0(Native Method)
at sun.reflect.NativeMethodAccessorImpl.invoke(NativeMethodAccessorImpl.java:62)
at sun.reflect.DelegatingMethodAccessorImpl.invoke(DelegatingMethodAccessorImpl.java:43)
at java.lang.reflect.Method.invoke(Method.java:498)
at org.testng.internal.MethodInvocationHelper.invokeMethod(MethodInvocationHelper.java:124)
at org.testng.internal.Invoker.invokeMethod(Invoker.java:583)
at org.testng.internal.Invoker.retryFailed(Invoker.java:839)
at org.testng.internal.Invoker.invokeTestMethods(Invoker.java:1010)
at org.testng.internal.TestMethodWorker.invokeTestMethods(TestMethodWorker.java:125)
at org.testng.internal.TestMethodWorker.run(TestMethodWorker.java:109)
at org.testng.TestRunner.privateRun(TestRunner.java:648)
at org.testng.TestRunner.run(TestRunner.java:505)
at org.testng.SuiteRunner.runTest(SuiteRunner.java:455)
at org.testng.SuiteRunner.access$000(SuiteRunner.java:40)
at org.testng.SuiteRunner$SuiteWorker.run(SuiteRunner.java:489)
at org.testng.internal.thread.ThreadUtil$1.call(ThreadUtil.java:52)
at java.util.concurrent.FutureTask.run(FutureTask.java:266)
at java.util.concurrent.ThreadPoolExecutor.runWorker(ThreadPoolExecutor.java:1149)
at java.util.concurrent.ThreadPoolExecutor$Worker.run(ThreadPoolExecutor.java:624)
at java.lang.Thread.run(Thread.java:748)
]]>
            </full-stacktrace>
          </exception> <!-- java.lang.AssertionError -->
          <reporter-output>
          </reporter-output>
        </test-method> <!-- test3 -->
        <test-method status="PASS" signature="resetPage()[pri:0, instance:TestClass@2344fc66]" name="resetPage" is-config="true" duration-ms="0" started-at="2019-05-23T17:52:38Z" finished-at="2019-05-23T17:52:38Z">
          <reporter-output>
          </reporter-output>
        </test-method> <!-- resetPage -->
        <test-method status="FAIL" signature="test3()[pri:0, instance:TestClass@2344fc66]" name="test3" duration-ms="1" started-at="2019-05-23T17:52:38Z" finished-at="2019-05-23T17:52:38Z">
          <exception class="java.lang.AssertionError">
            <message>
              <![CDATA[expected [2] but found [1]]]>
            </message>
            <full-stacktrace>
              <![CDATA[java.lang.AssertionError: expected [2] but found [1]
at org.testng.Assert.fail(Assert.java:96)
at org.testng.Assert.failNotEquals(Assert.java:776)
at org.testng.Assert.assertEqualsImpl(Assert.java:137)
at org.testng.Assert.assertEquals(Assert.java:118)
at org.testng.Assert.assertEquals(Assert.java:453)
at org.testng.Assert.assertEquals(Assert.java:463)
at TestClass.test3(TestClass.java:77)
at sun.reflect.NativeMethodAccessorImpl.invoke0(Native Method)
at sun.reflect.NativeMethodAccessorImpl.invoke(NativeMethodAccessorImpl.java:62)
at sun.reflect.DelegatingMethodAccessorImpl.invoke(DelegatingMethodAccessorImpl.java:43)
at java.lang.reflect.Method.invoke(Method.java:498)
at org.testng.internal.MethodInvocationHelper.invokeMethod(MethodInvocationHelper.java:124)
at org.testng.internal.Invoker.invokeMethod(Invoker.java:583)
at org.testng.internal.Invoker.retryFailed(Invoker.java:839)
at org.testng.internal.Invoker.invokeTestMethods(Invoker.java:1010)
at org.testng.internal.TestMethodWorker.invokeTestMethods(TestMethodWorker.java:125)
at org.testng.internal.TestMethodWorker.run(TestMethodWorker.java:109)
at org.testng.TestRunner.privateRun(TestRunner.java:648)
at org.testng.TestRunner.run(TestRunner.java:505)
at org.testng.SuiteRunner.runTest(SuiteRunner.java:455)
at org.testng.SuiteRunner.access$000(SuiteRunner.java:40)
at org.testng.SuiteRunner$SuiteWorker.run(SuiteRunner.java:489)
at org.testng.internal.thread.ThreadUtil$1.call(ThreadUtil.java:52)
at java.util.concurrent.FutureTask.run(FutureTask.java:266)
at java.util.concurrent.ThreadPoolExecutor.runWorker(ThreadPoolExecutor.java:1149)
at java.util.concurrent.ThreadPoolExecutor$Worker.run(ThreadPoolExecutor.java:624)
at java.lang.Thread.run(Thread.java:748)
]]>
            </full-stacktrace>
          </exception> <!-- java.lang.AssertionError -->
          <reporter-output>
          </reporter-output>
        </test-method> <!-- test3 -->
        <test-method status="PASS" signature="resetPage()[pri:0, instance:TestClass@2344fc66]" name="resetPage" is-config="true" duration-ms="0" started-at="2019-05-23T17:52:38Z" finished-at="2019-05-23T17:52:38Z">
          <reporter-output>
          </reporter-output>
        </test-method> <!-- resetPage -->
        <test-method status="SKIP" signature="test4()[pri:0, instance:TestClass@2344fc66]" name="test4" duration-ms="0" started-at="2019-05-23T17:52:38Z" finished-at="2019-05-23T17:52:38Z">
          <exception class="java.lang.AssertionError">
            <message>
              <![CDATA[expected [2] but found [1]]]>
            </message>
            <full-stacktrace>
              <![CDATA[java.lang.AssertionError: expected [2] but found [1]
at org.testng.Assert.fail(Assert.java:96)
at org.testng.Assert.failNotEquals(Assert.java:776)
at org.testng.Assert.assertEqualsImpl(Assert.java:137)
at org.testng.Assert.assertEquals(Assert.java:118)
at org.testng.Assert.assertEquals(Assert.java:453)
at org.testng.Assert.assertEquals(Assert.java:463)
at TestClass.test4(TestClass.java:83)
at sun.reflect.NativeMethodAccessorImpl.invoke0(Native Method)
at sun.reflect.NativeMethodAccessorImpl.invoke(NativeMethodAccessorImpl.java:62)
at sun.reflect.DelegatingMethodAccessorImpl.invoke(DelegatingMethodAccessorImpl.java:43)
at java.lang.reflect.Method.invoke(Method.java:498)
at org.testng.internal.MethodInvocationHelper.invokeMethod(MethodInvocationHelper.java:124)
at org.testng.internal.Invoker.invokeMethod(Invoker.java:583)
at org.testng.internal.Invoker.invokeTestMethod(Invoker.java:719)
at org.testng.internal.Invoker.invokeTestMethods(Invoker.java:989)
at org.testng.internal.TestMethodWorker.invokeTestMethods(TestMethodWorker.java:125)
at org.testng.internal.TestMethodWorker.run(TestMethodWorker.java:109)
at org.testng.TestRunner.privateRun(TestRunner.java:648)
at org.testng.TestRunner.run(TestRunner.java:505)
at org.testng.SuiteRunner.runTest(SuiteRunner.java:455)
at org.testng.SuiteRunner.access$000(SuiteRunner.java:40)
at org.testng.SuiteRunner$SuiteWorker.run(SuiteRunner.java:489)
at org.testng.internal.thread.ThreadUtil$1.call(ThreadUtil.java:52)
at java.util.concurrent.FutureTask.run(FutureTask.java:266)
at java.util.concurrent.ThreadPoolExecutor.runWorker(ThreadPoolExecutor.java:1149)
at java.util.concurrent.ThreadPoolExecutor$Worker.run(ThreadPoolExecutor.java:624)
at java.lang.Thread.run(Thread.java:748)
]]>
            </full-stacktrace>
          </exception> <!-- java.lang.AssertionError -->
          <reporter-output>
          </reporter-output>
        </test-method> <!-- test4 -->
        <test-method status="SKIP" signature="test4()[pri:0, instance:TestClass@2344fc66]" name="test4" duration-ms="0" started-at="2019-05-23T17:52:38Z" finished-at="2019-05-23T17:52:38Z">
          <exception class="java.lang.AssertionError">
            <message>
              <![CDATA[expected [2] but found [1]]]>
            </message>
            <full-stacktrace>
              <![CDATA[java.lang.AssertionError: expected [2] but found [1]
at org.testng.Assert.fail(Assert.java:96)
at org.testng.Assert.failNotEquals(Assert.java:776)
at org.testng.Assert.assertEqualsImpl(Assert.java:137)
at org.testng.Assert.assertEquals(Assert.java:118)
at org.testng.Assert.assertEquals(Assert.java:453)
at org.testng.Assert.assertEquals(Assert.java:463)
at TestClass.test4(TestClass.java:83)
at sun.reflect.NativeMethodAccessorImpl.invoke0(Native Method)
at sun.reflect.NativeMethodAccessorImpl.invoke(NativeMethodAccessorImpl.java:62)
at sun.reflect.DelegatingMethodAccessorImpl.invoke(DelegatingMethodAccessorImpl.java:43)
at java.lang.reflect.Method.invoke(Method.java:498)
at org.testng.internal.MethodInvocationHelper.invokeMethod(MethodInvocationHelper.java:124)
at org.testng.internal.Invoker.invokeMethod(Invoker.java:583)
at org.testng.internal.Invoker.retryFailed(Invoker.java:839)
at org.testng.internal.Invoker.invokeTestMethods(Invoker.java:1010)
at org.testng.internal.TestMethodWorker.invokeTestMethods(TestMethodWorker.java:125)
at org.testng.internal.TestMethodWorker.run(TestMethodWorker.java:109)
at org.testng.TestRunner.privateRun(TestRunner.java:648)
at org.testng.TestRunner.run(TestRunner.java:505)
at org.testng.SuiteRunner.runTest(SuiteRunner.java:455)
at org.testng.SuiteRunner.access$000(SuiteRunner.java:40)
at org.testng.SuiteRunner$SuiteWorker.run(SuiteRunner.java:489)
at org.testng.internal.thread.ThreadUtil$1.call(ThreadUtil.java:52)
at java.util.concurrent.FutureTask.run(FutureTask.java:266)
at java.util.concurrent.ThreadPoolExecutor.runWorker(ThreadPoolExecutor.java:1149)
at java.util.concurrent.ThreadPoolExecutor$Worker.run(ThreadPoolExecutor.java:624)
at java.lang.Thread.run(Thread.java:748)
]]>
            </full-stacktrace>
          </exception> <!-- java.lang.AssertionError -->
          <reporter-output>
          </reporter-output>
        </test-method> <!-- test4 -->
        <test-method status="PASS" signature="resetPage()[pri:0, instance:TestClass@2344fc66]" name="resetPage" is-config="true" duration-ms="0" started-at="2019-05-23T17:52:38Z" finished-at="2019-05-23T17:52:38Z">
          <reporter-output>
          </reporter-output>
        </test-method> <!-- resetPage -->
        <test-method status="FAIL" signature="test4()[pri:0, instance:TestClass@2344fc66]" name="test4" duration-ms="0" started-at="2019-05-23T17:52:38Z" finished-at="2019-05-23T17:52:38Z">
          <exception class="java.lang.AssertionError">
            <message>
              <![CDATA[expected [2] but found [1]]]>
            </message>
            <full-stacktrace>
              <![CDATA[java.lang.AssertionError: expected [2] but found [1]
at org.testng.Assert.fail(Assert.java:96)
at org.testng.Assert.failNotEquals(Assert.java:776)
at org.testng.Assert.assertEqualsImpl(Assert.java:137)
at org.testng.Assert.assertEquals(Assert.java:118)
at org.testng.Assert.assertEquals(Assert.java:453)
at org.testng.Assert.assertEquals(Assert.java:463)
at TestClass.test4(TestClass.java:83)
at sun.reflect.NativeMethodAccessorImpl.invoke0(Native Method)
at sun.reflect.NativeMethodAccessorImpl.invoke(NativeMethodAccessorImpl.java:62)
at sun.reflect.DelegatingMethodAccessorImpl.invoke(DelegatingMethodAccessorImpl.java:43)
at java.lang.reflect.Method.invoke(Method.java:498)
at org.testng.internal.MethodInvocationHelper.invokeMethod(MethodInvocationHelper.java:124)
at org.testng.internal.Invoker.invokeMethod(Invoker.java:583)
at org.testng.internal.Invoker.retryFailed(Invoker.java:839)
at org.testng.internal.Invoker.invokeTestMethods(Invoker.java:1010)
at org.testng.internal.TestMethodWorker.invokeTestMethods(TestMethodWorker.java:125)
at org.testng.internal.TestMethodWorker.run(TestMethodWorker.java:109)
at org.testng.TestRunner.privateRun(TestRunner.java:648)
at org.testng.TestRunner.run(TestRunner.java:505)
at org.testng.SuiteRunner.runTest(SuiteRunner.java:455)
at org.testng.SuiteRunner.access$000(SuiteRunner.java:40)
at org.testng.SuiteRunner$SuiteWorker.run(SuiteRunner.java:489)
at org.testng.internal.thread.ThreadUtil$1.call(ThreadUtil.java:52)
at java.util.concurrent.FutureTask.run(FutureTask.java:266)
at java.util.concurrent.ThreadPoolExecutor.runWorker(ThreadPoolExecutor.java:1149)
at java.util.concurrent.ThreadPoolExecutor$Worker.run(ThreadPoolExecutor.java:624)
at java.lang.Thread.run(Thread.java:748)
]]>
            </full-stacktrace>
          </exception> <!-- java.lang.AssertionError -->
          <reporter-output>
          </reporter-output>
        </test-method> <!-- test4 -->
        <test-method status="PASS" signature="resetPage()[pri:0, instance:TestClass@2344fc66]" name="resetPage" is-config="true" duration-ms="0" started-at="2019-05-23T17:52:38Z" finished-at="2019-05-23T17:52:38Z">
          <reporter-output>
          </reporter-output>
        </test-method> <!-- resetPage -->
        <test-method status="PASS" signature="resetPage()[pri:0, instance:TestClass@2344fc66]" name="resetPage" is-config="true" duration-ms="0" started-at="2019-05-23T17:52:38Z" finished-at="2019-05-23T17:52:38Z">
          <reporter-output>
          </reporter-output>
        </test-method> <!-- resetPage -->
        <test-method status="PASS" signature="test5()[pri:0, instance:TestClass@2344fc66]" name="test5" duration-ms="0" started-at="2019-05-23T17:52:38Z" finished-at="2019-05-23T17:52:38Z">
          <reporter-output>
          </reporter-output>
        </test-method> <!-- test5 -->
      </class> <!-- TestClass -->
    </test> <!-- CompatibilityTesting -->
  </suite> <!-- StockCircles Automation Testing -->
</testng-results>
