<?xml version="1.0" encoding="UTF-8"?>
<!-- Generated by org.testng.reporters.JUnitReportReporter -->
<testsuite skipped="4" hostname="192.168.0.101" name="TestClass" tests="8" failures="2" timestamp="23 五月 2019 17:52:39 GMT" time="0.004" errors="0">
  <testcase name="test1" time="0.000" classname="TestClass"/>
  <testcase name="test4" time="0.000" classname="TestClass">
    <failure type="java.lang.AssertionError" message="expected [2] but found [1]">
      <![CDATA[java.lang.AssertionError: expected [2] but found [1]
at org.testng.Assert.fail(Assert.java:96)
at org.testng.Assert.failNotEquals(Assert.java:776)
at org.testng.Assert.assertEqualsImpl(Assert.java:137)
at org.testng.Assert.assertEquals(Assert.java:118)
at org.testng.Assert.assertEquals(Assert.java:453)
at org.testng.Assert.assertEquals(Assert.java:463)
at TestClass.test4(TestClass.java:83)
at sun.reflect.NativeMethodAccessorImpl.invoke0(Native Method)
at sun.reflect.NativeMethodAccessorImpl.invoke(NativeMethodAccessorImpl.java:62)
at sun.reflect.DelegatingMethodAccessorImpl.invoke(DelegatingMethodAccessorImpl.java:43)
at java.lang.reflect.Method.invoke(Method.java:498)
at org.testng.internal.MethodInvocationHelper.invokeMethod(MethodInvocationHelper.java:124)
at org.testng.internal.Invoker.invokeMethod(Invoker.java:583)
at org.testng.internal.Invoker.retryFailed(Invoker.java:839)
at org.testng.internal.Invoker.invokeTestMethods(Invoker.java:1010)
at org.testng.internal.TestMethodWorker.invokeTestMethods(TestMethodWorker.java:125)
at org.testng.internal.TestMethodWorker.run(TestMethodWorker.java:109)
at org.testng.TestRunner.privateRun(TestRunner.java:648)
at org.testng.TestRunner.run(TestRunner.java:505)
at org.testng.SuiteRunner.runTest(SuiteRunner.java:455)
at org.testng.SuiteRunner.access$000(SuiteRunner.java:40)
at org.testng.SuiteRunner$SuiteWorker.run(SuiteRunner.java:489)
at org.testng.internal.thread.ThreadUtil$1.call(ThreadUtil.java:52)
at java.util.concurrent.FutureTask.run(FutureTask.java:266)
at java.util.concurrent.ThreadPoolExecutor.runWorker(ThreadPoolExecutor.java:1149)
at java.util.concurrent.ThreadPoolExecutor$Worker.run(ThreadPoolExecutor.java:624)
at java.lang.Thread.run(Thread.java:748)
]]>
    </failure>
  </testcase> <!-- test4 -->
  <testcase name="test3" time="0.002" classname="TestClass">
    <skipped/>
  </testcase> <!-- test3 -->
  <testcase name="test4" time="0.000" classname="TestClass">
    <skipped/>
  </testcase> <!-- test4 -->
  <testcase name="test5" time="0.000" classname="TestClass"/>
  <testcase name="test3" time="0.001" classname="TestClass">
    <failure type="java.lang.AssertionError" message="expected [2] but found [1]">
      <![CDATA[java.lang.AssertionError: expected [2] but found [1]
at org.testng.Assert.fail(Assert.java:96)
at org.testng.Assert.failNotEquals(Assert.java:776)
at org.testng.Assert.assertEqualsImpl(Assert.java:137)
at org.testng.Assert.assertEquals(Assert.java:118)
at org.testng.Assert.assertEquals(Assert.java:453)
at org.testng.Assert.assertEquals(Assert.java:463)
at TestClass.test3(TestClass.java:77)
at sun.reflect.NativeMethodAccessorImpl.invoke0(Native Method)
at sun.reflect.NativeMethodAccessorImpl.invoke(NativeMethodAccessorImpl.java:62)
at sun.reflect.DelegatingMethodAccessorImpl.invoke(DelegatingMethodAccessorImpl.java:43)
at java.lang.reflect.Method.invoke(Method.java:498)
at org.testng.internal.MethodInvocationHelper.invokeMethod(MethodInvocationHelper.java:124)
at org.testng.internal.Invoker.invokeMethod(Invoker.java:583)
at org.testng.internal.Invoker.retryFailed(Invoker.java:839)
at org.testng.internal.Invoker.invokeTestMethods(Invoker.java:1010)
at org.testng.internal.TestMethodWorker.invokeTestMethods(TestMethodWorker.java:125)
at org.testng.internal.TestMethodWorker.run(TestMethodWorker.java:109)
at org.testng.TestRunner.privateRun(TestRunner.java:648)
at org.testng.TestRunner.run(TestRunner.java:505)
at org.testng.SuiteRunner.runTest(SuiteRunner.java:455)
at org.testng.SuiteRunner.access$000(SuiteRunner.java:40)
at org.testng.SuiteRunner$SuiteWorker.run(SuiteRunner.java:489)
at org.testng.internal.thread.ThreadUtil$1.call(ThreadUtil.java:52)
at java.util.concurrent.FutureTask.run(FutureTask.java:266)
at java.util.concurrent.ThreadPoolExecutor.runWorker(ThreadPoolExecutor.java:1149)
at java.util.concurrent.ThreadPoolExecutor$Worker.run(ThreadPoolExecutor.java:624)
at java.lang.Thread.run(Thread.java:748)
]]>
    </failure>
  </testcase> <!-- test3 -->
  <testcase name="test3" time="0.001" classname="TestClass">
    <skipped/>
  </testcase> <!-- test3 -->
  <testcase name="test4" time="0.000" classname="TestClass">
    <skipped/>
  </testcase> <!-- test4 -->
</testsuite> <!-- TestClass -->
